Workbook

Sheet MB
B1: Gatunek | C1: Nastrój | D1: Instrument | E1: Zastosowanie | F1: Spójność | G1: Melodyjność | H1: Oryginalność | I1: Autentyczność | J1: Klarowność | K1: Ocena ogólna | L1: SUMA
A2: [ACE-Step] Pathetic film music for orchestra, without choir, f-minor, 80 bpm, 100 seconds | N2: Skala 1-5
A3: Sample1 | B3: 3 | C3: 3 | D3: 2 | E3: 2 | F3: 2 | G3: 3 | H3: 2 | I3: 2 | J3: 3 | K3: 5 | L3: =SUM(B3:K3) -> 27 | N3: Ocena ogólna: 1-10
A4: Sample2 | B4: 3 | C4: 4 | D4: 3 | E4: 3 | F4: 3 | G4: 3 | H4: 3 | I4: 4 | J4: 4 | K4: 5 | L4: =SUM(B4:K4) -> 35
A5: Sample3 | B5: 2 | C5: 2 | D5: 4 | E5: 1 | F5: 1 | G5: 2 | H5: 2 | I5: 1 | J5: 3 | K5: 4 | L5: =SUM(B5:K5) -> 22
A6: Sample4 | B6: 3 | C6: 3 | D6: 4 | E6: 2 | F6: 2 | G6: 3 | H6: 2 | I6: 2 | J6: 3 | K6: 4 | L6: =SUM(B6:K6) -> 28
A7: Sample5 | B7: 4 | C7: 3 | D7: 4 | E7: 2 | F7: 2 | G7: 3 | H7: 2 | I7: 2 | J7: 3 | K7: 5 | L7: =SUM(B7:K7) -> 30
A8: [ACE-Step] Energetic techno, synthesizer, e-minor, 140 bpm, 100 seconds
A9: Sample1 | B9: 3 | C9: 3 | D9: 3 | E9: 2 | F9: 2 | G9: 2 | H9: 2 | I9: 2 | J9: 2 | K9: 3 | L9: =SUM(B9:K9) -> 24
A10: Sample2 | B10: 2 | C10: 2 | D10: 1 | E10: 1 | F10: 3 | G10: 3 | H10: 2 | I10: 3 | J10: 3 | K10: 4 | L10: =SUM(B10:K10) -> 24
A11: Sample3 | B11: 1 | C11: 2 | D11: 2 | E11: 1 | F11: 3 | G11: 3 | H11: 2 | I11: 3 | J11: 4 | K11: 5 | L11: =SUM(B11:K11) -> 26
A12: Sample4 | B12: 3 | C12: 3 | D12: 2 | E12: 1 | F12: 2 | G12: 2 | H12: 2 | I12: 2 | J12: 3 | K12: 4 | L12: =SUM(B12:K12) -> 24
A13: Sample5 | B13: 3 | C13: 3 | D13: 3 | E13: 2 | F13: 3 | G13: 3 | H13: 3 | I13: 3 | J13: 3 | K13: 5 | L13: =SUM(B13:K13) -> 31
A14: [ACE-Step] Relaxing lofi with piano, e-major, 100 bpm, 100 seconds
A15: Sample1 | B15: 1 | C15: 3 | D15: 4 | E15: 2 | F15: 3 | G15: 3 | H15: 2 | I15: 3 | J15: 4 | K15: 4 | L15: =SUM(B15:K15) -> 29
A16: Sample2 | B16: 4 | C16: 4 | D16: 4 | E16: 3 | F16: 3 | G16: 3 | H16: 2 | I16: 2 | J16: 3 | K16: 6 | L16: =SUM(B16:K16) -> 34
A17: Sample3 | B17: 1 | C17: 2 | D17: 3 | E17: 1 | F17: 2 | G17: 2 | H17: 2 | I17: 2 | J17: 2 | K17: 3 | L17: =SUM(B17:K17) -> 20
A18: Sample4 | B18: 3 | C18: 2 | D18: 3 | E18: 1 | F18: 2 | G18: 2 | H18: 2 | I18: 2 | J18: 3 | K18: 3 | L18: =SUM(B18:K18) -> 23
A19: Sample5 | B19: 1 | C19: 3 | D19: 3 | E19: 2 | F19: 3 | G19: 2 | H19: 2 | I19: 2 | J19: 3 | K19: 4 | L19: =SUM(B19:K19) -> 25
A20: [DiffRhythm] Pathetic film music for orchestra, without choir, f-minor, 80 bpm, 100 seconds
A21: Sample1 | B21: 2 | C21: 1 | D21: 2 | E21: 1 | F21: 2 | G21: 2 | H21: 3 | I21: 2 | J21: 2 | K21: 2 | L21: =SUM(B21:K21) -> 19
A22: Sample2 | B22: 2 | C22: 1 | D22: 2 | E22: 1 | F22: 2 | G22: 3 | H22: 2 | I22: 2 | J22: 2 | K22: 3 | L22: =SUM(B22:K22) -> 20
A23: Sample3 | B23: 2 | C23: 2 | D23: 3 | E23: 2 | F23: 3 | G23: 2 | H23: 2 | I23: 2 | J23: 2 | K23: 3 | L23: =SUM(B23:K23) -> 23
A24: Sample4 | B24: 3 | C24: 3 | D24: 3 | E24: 3 | F24: 2 | G24: 3 | H24: 2 | I24: 2 | J24: 2 | K24: 4 | L24: =SUM(B24:K24) -> 27
A25: Sample5 | B25: 3 | C25: 2 | D25: 3 | E25: 2 | F25: 2 | G25: 2 | H25: 2 | I25: 2 | J25: 2 | K25: 3 | L25: =SUM(B25:K25) -> 23
A26: [DiffRhythm] Energetic techno, synthesizer, e-minor, 140 bpm, 100 seconds
A27: Sample1 | B27: 2 | C27: 2 | D27: 2 | E27: 2 | F27: 2 | G27: 2 | H27: 2 | I27: 2 | J27: 3 | K27: 3 | L27: =SUM(B27:K27) -> 22
A28: Sample2 | B28: 2 | C28: 3 | D28: 2 | E28: 2 | F28: 2 | G28: 2 | H28: 2 | I28: 3 | J28: 3 | K28: 4 | L28: =SUM(B28:K28) -> 25
A29: Sample3 | B29: 1 | C29: 2 | D29: 1 | E29: 2 | F29: 3 | G29: 3 | H29: 3 | I29: 3 | J29: 2 | K29: 4 | L29: =SUM(B29:K29) -> 24
A30: Sample4 | B30: 2 | C30: 3 | D30: 1 | E30: 2 | F30: 3 | G30: 2 | H30: 2 | I30: 3 | J30: 3 | K30: 3 | L30: =SUM(B30:K30) -> 24
A31: Sample5 | B31: 3 | C31: 3 | D31: 3 | E31: 3 | F31: 2 | G31: 3 | H31: 2 | I31: 2 | J31: 3 | K31: 5 | L31: =SUM(B31:K31) -> 29
A32: [DiffRhythm] Relaxing lofi with piano, e-major, 100 bpm, 100 seconds
A33: Sample1 | B33: 2 | C33: 2 | D33: 4 | E33: 3 | F33: 3 | G33: 2 | H33: 3 | I33: 2 | J33: 3 | K33: 3 | L33: =SUM(B33:K33) -> 27
A34: Sample2 | B34: 1 | C34: 1 | D34: 1 | E34: 1 | F34: 3 | G34: 2 | H34: 2 | I34: 3 | J34: 3 | K34: 3 | L34: =SUM(B34:K34) -> 20
A35: Sample3 | B35: 4 | C35: 3 | D35: 3 | E35: 4 | F35: 3 | G35: 3 | H35: 2 | I35: 3 | J35: 3 | K35: 5 | L35: =SUM(B35:K35) -> 33
A36: Sample4 | B36: 2 | C36: 2 | D36: 2 | E36: 2 | F36: 2 | G36: 2 | H36: 2 | I36: 2 | J36: 2 | K36: 3 | L36: =SUM(B36:K36) -> 21
A37: Sample5 | B37: 3 | C37: 2 | D37: 3 | E37: 2 | F37: 3 | G37: 3 | H37: 2 | I37: 2 | J37: 3 | K37: 4 | L37: =SUM(B37:K37) -> 27
A38: [Stable Audio] Pathetic film music for orchestra, without choir, f-minor, 80 bpm, 100 seconds
A39: Sample1 | B39: 4 | C39: 4 | D39: 2 | E39: 4 | F39: 4 | G39: 3 | H39: 2 | I39: 4 | J39: 4 | K39: 6 | L39: =SUM(B39:K39) -> 37
A40: Sample2 | B40: 4 | C40: 3 | D40: 4 | E40: 4 | F40: 4 | G40: 3 | H40: 2 | I40: 3 | J40: 4 | K40: 6 | L40: =SUM(B40:K40) -> 37
...

Sheet JW
B1: Gatunek | C1: Nastrój | D1: Instrument | E1: Zastosowanie | F1: Spójność | G1: Melodyjność | H1: Oryginalność | I1: Autentyczność | J1: Klarowność | K1: Ocena ogólna | L1: SUMA
A2: [ACE-Step] Pathetic film music for orchestra, without choir, f-minor, 80 bpm, 100 seconds | N2: Skala 1-5
A3: Sample1 | B3: 2 | C3: 2 | D3: 1 | E3: 2 | F3: 1 | G3: 2 | H3: 2 | I3: 1 | J3: 1 | K3: 2 | L3: =SUM(B3:K3) -> 16 | N3: Ocena ogólna: 1-10
A4: Sample2 | B4: 3 | C4: 2 | D4: 2 | E4: 2 | F4: 3 | G4: 2 | H4: 2 | I4: 3 | J4: 2 | K4: 3 | L4: =SUM(B4:K4) -> 24
A5: Sample3 | B5: 4 | C5: 3 | D5: 4 | E5: 4 | F5: 3 | G5: 4 | H5: 3 | I5: 4 | J5: 3 | K5: 5 | L5: =SUM(B5:K5) -> 37
A6: Sample4 | B6: 3 | C6: 2 | D6: 2 | E6: 2 | F6: 3 | G6: 2 | H6: 3 | I6: 2 | J6: 2 | K6: 4 | L6: =SUM(B6:K6) -> 25
A7: Sample5 | B7: 3 | C7: 2 | D7: 3 | E7: 3 | F7: 2 | G7: 3 | H7: 2 | I7: 2 | J7: 2 | K7: 4 | L7: =SUM(B7:K7) -> 26
A8: [ACE-Step] Energetic techno, synthesizer, e-minor, 140 bpm, 100 seconds
A9: Sample1 | B9: 3 | C9: 3 | D9: 3 | E9: 3 | F9: 2 | G9: 2 | H9: 2 | I9: 2 | J9: 2 | K9: 5 | L9: =SUM(B9:K9) -> 27
A10: Sample2 | B10: 2 | C10: 3 | D10: 3 | E10: 2 | F10: 2 | G10: 2 | H10: 2 | I10: 3 | J10: 2 | K10: 5 | L10: =SUM(B10:K10) -> 26
A11: Sample3 | B11: 1 | C11: 2 | D11: 2 | E11: 2 | F11: 3 | G11: 3 | H11: 3 | I11: 2 | J11: 2 | K11: 4 | L11: =SUM(B11:K11) -> 24
A12: Sample4 | B12: 2 | C12: 2 | D12: 2 | E12: 2 | F12: 4 | G12: 4 | H12: 3 | I12: 3 | J12: 3 | K12: 5 | L12: =SUM(B12:K12) -> 30
A13: Sample5 | B13: 3 | C13: 3 | D13: 3 | E13: 2 | F13: 3 | G13: 2 | H13: 2 | I13: 3 | J13: 2 | K13: 4 | L13: =SUM(B13:K13) -> 27
A14: [ACE-Step] Relaxing lofi with piano, e-major, 100 bpm, 100 seconds
A15: Sample1 | B15: 1 | C15: 2 | D15: 2 | E15: 2 | F15: 2 | G15: 3 | H15: 2 | I15: 1 | J15: 2 | K15: 3 | L15: =SUM(B15:K15) -> 20
A16: Sample2 | B16: 4 | C16: 4 | D16: 3 | E16: 3 | F16: 3 | G16: 3 | H16: 3 | I16: 2 | J16: 2 | K16: 5 | L16: =SUM(B16:K16) -> 32
A17: Sample3 | B17: 1 | C17: 1 | D17: 2 | E17: 1 | F17: 2 | G17: 2 | H17: 2 | I17: 1 | J17: 2 | K17: 2 | L17: =SUM(B17:K17) -> 16
A18: Sample4 | B18: 4 | C18: 2 | D18: 3 | E18: 2 | F18: 1 | G18: 2 | H18: 2 | I18: 1 | J18: 1 | K18: 2 | L18: =SUM(B18:K18) -> 20
A19: Sample5 | B19: 1 | C19: 2 | D19: 1 | E19: 2 | F19: 2 | G19: 2 | H19: 2 | I19: 1 | J19: 2 | K19: 3 | L19: =SUM(B19:K19) -> 18
A20: [DiffRhythm] Pathetic film music for orchestra, without choir, f-minor, 80 bpm, 100 seconds
A21: Sample1 | B21: 1 | C21: 1 | D21: 1 | E21: 2 | F21: 2 | G21: 2 | H21: 2 | I21: 1 | J21: 1 | K21: 2 | L21: =SUM(B21:K21) -> 15
A22: Sample2 | B22: 1 | C22: 1 | D22: 1 | E22: 1 | F22: 2 | G22: 2 | H22: 2 | I22: 1 | J22: 1 | K22: 2 | L22: =SUM(B22:K22) -> 14
A23: Sample3 | B23: 2 | C23: 3 | D23: 1 | E23: 2 | F23: 2 | G23: 1 | H23: 2 | I23: 1 | J23: 2 | K23: 2 | L23: =SUM(B23:K23) -> 18
A24: Sample4 | B24: 2 | C24: 2 | D24: 1 | E24: 2 | F24: 1 | G24: 1 | H24: 2 | I24: 1 | J24: 1 | K24: 2 | L24: =SUM(B24:K24) -> 15
A25: Sample5 | B25: 3 | C25: 3 | D25: 3 | E25: 3 | F25: 3 | G25: 3 | H25: 3 | I25: 2 | J25: 3 | K25: 5 | L25: =SUM(B25:K25) -> 31
A26: [DiffRhythm] Energetic techno, synthesizer, e-minor, 140 bpm, 100 seconds
A27: Sample1 | B27: 2 | C27: 2 | D27: 2 | E27: 2 | F27: 1 | G27: 2 | H27: 1 | I27: 2 | J27: 2 | K27: 3 | L27: =SUM(B27:K27) -> 19
A28: Sample2 | B28: 2 | C28: 3 | D28: 2 | E28: 3 | F28: 2 | G28: 2 | H28: 2 | I28: 2 | J28: 2 | K28: 3 | L28: =SUM(B28:K28) -> 23
A29: Sample3 | B29: 1 | C29: 2 | D29: 1 | E29: 1 | F29: 2 | G29: 2 | H29: 2 | I29: 2 | J29: 2 | K29: 2 | L29: =SUM(B29:K29) -> 17
A30: Sample4 | B30: 3 | C30: 2 | D30: 1 | E30: 2 | F30: 2 | G30: 1 | H30: 2 | I30: 2 | J30: 1 | K30: 3 | L30: =SUM(B30:K30) -> 19
A31: Sample5 | B31: 3 | C31: 2 | D31: 3 | E31: 3 | F31: 3 | G31: 2 | H31: 2 | I31: 3 | J31: 3 | K31: 5 | L31: =SUM(B31:K31) -> 29
A32: [DiffRhythm] Relaxing lofi with piano, e-major, 100 bpm, 100 seconds
A33: Sample1 | B33: 1 | C33: 2 | D33: 3 | E33: 2 | F33: 3 | G33: 3 | H33: 2 | I33: 1 | J33: 2 | K33: 3 | L33: =SUM(B33:K33) -> 22
A34: Sample2 | B34: 1 | C34: 1 | D34: 1 | E34: 1 | F34: 2 | G34: 2 | H34: 2 | I34: 1 | J34: 2 | K34: 1 | L34: =SUM(B34:K34) -> 14
A35: Sample3 | B35: 5 | C35: 5 | D35: 4 | E35: 4 | F35: 5 | G35: 4 | H35: 3 | I35: 2 | J35: 3 | K35: 8 | L35: =SUM(B35:K35) -> 43
A36: Sample4 | B36: 1 | C36: 1 | D36: 1 | E36: 1 | F36: 2 | G36: 2 | H36: 3 | I36: 2 | J36: 2 | K36: 1 | L36: =SUM(B36:K36) -> 16
A37: Sample5 | B37: 3 | C37: 3 | D37: 2 | E37: 2 | F37: 3 | G37: 3 | H37: 2 | I37: 1 | J37: 2 | K37: 4 | L37: =SUM(B37:K37) -> 25
A38: [Stable Audio] Pathetic film music for orchestra, without choir, f-minor, 80 bpm, 100 seconds
A39: Sample1 | B39: 5 | C39: 5 | D39: 2 | E39: 5 | F39: 4 | G39: 4 | H39: 4 | I39: 4 | J39: 4 | K39: 7 | L39: =SUM(B39:K39) -> 44
A40: Sample2 | B40: 4 | C40: 4 | D40: 4 | E40: 4 | F40: 4 | G40: 5 | H40: 4 | I40: 3 | J40: 4 | K40: 7 | L40: =SUM(B40:K40) -> 43
...

Sheet SK
B1: Gatunek | C1: Nastrój | D1: Instrument | E1: Zastosowanie | F1: Spójność | G1: Melodyjność | H1: Oryginalność | I1: Autentyczność | J1: Klarowność | K1: Ocena ogólna | L1: SUMA
A2: [ACE-Step] Pathetic film music for orchestra, without choir, f-minor, 80 bpm, 100 seconds | N2: Skala 1-5
A3: Sample1 | B3: 4 | C3: 3 | D3: 3 | E3: 4 | F3: 5 | G3: 3 | H3: 4 | I3: 2 | J3: 4 | K3: 5 | L3: =SUM(B3:K3) -> 37 | N3: Ocena ogólna: 1-10
A4: Sample2 | B4: 5 | C4: 3 | D4: 3 | E4: 2 | F4: 4 | G4: 4 | H4: 3 | I4: 5 | J4: 4 | K4: 7 | L4: =SUM(B4:K4) -> 40
A5: Sample3 | B5: 5 | C5: 3 | D5: 4 | E5: 3 | F5: 4 | G5: 4 | H5: 5 | I5: 5 | J5: 3 | K5: 7 | L5: =SUM(B5:K5) -> 43
A6: Sample4 | B6: 5 | C6: 5 | D6: 3 | E6: 4 | F6: 4 | G6: 3 | H6: 4 | I6: 4 | J6: 4 | K6: 5 | L6: =SUM(B6:K6) -> 41
A7: Sample5 | B7: 4 | C7: 4 | D7: 4 | E7: 4 | F7: 4 | G7: 3 | H7: 5 | I7: 5 | J7: 2 | K7: 4 | L7: =SUM(B7:K7) -> 39
A8: [ACE-Step] Energetic techno, synthesizer, e-minor, 140 bpm, 100 seconds
A9: Sample1 | B9: 4 | C9: 3 | D9: 3 | E9: 4 | F9: 5 | G9: 4 | H9: 4 | I9: 5 | J9: 3 | K9: 5 | L9: =SUM(B9:K9) -> 40
A10: Sample2 | B10: 3 | C10: 3 | D10: 2 | E10: 3 | F10: 4 | G10: 4 | H10: 3 | I10: 4 | J10: 2 | K10: 4 | L10: =SUM(B10:K10) -> 32
A11: Sample3 | B11: 3 | C11: 2 | D11: 2 | E11: 2 | F11: 4 | G11: 4 | H11: 3 | I11: 3 | J11: 2 | K11: 4 | L11: =SUM(B11:K11) -> 29
A12: Sample4 | B12: 4 | C12: 4 | D12: 3 | E12: 3 | F12: 3 | G12: 2 | H12: 3 | I12: 3 | J12: 2 | K12: 5 | L12: =SUM(B12:K12) -> 32
A13: Sample5 | B13: 4 | C13: 4 | D13: 3 | E13: 4 | F13: 5 | G13: 4 | H13: 4 | I13: 5 | J13: 4 | K13: 7 | L13: =SUM(B13:K13) -> 44
A14: [ACE-Step] Relaxing lofi with piano, e-major, 100 bpm, 100 seconds
A15: Sample1 | B15: 3 | C15: 3 | D15: 4 | E15: 4 | F15: 5 | G15: 4 | H15: 2 | I15: 3 | J15: 4 | K15: 4 | L15: =SUM(B15:K15) -> 36
A16: Sample2 | B16: 5 | C16: 4 | D16: 3 | E16: 3 | F16: 2 | G16: 4 | H16: 4 | I16: 4 | J16: 3 | K16: 5 | L16: =SUM(B16:K16) -> 37
A17: Sample3 | B17: 2 | C17: 3 | D17: 4 | E17: 3 | F17: 4 | G17: 2 | H17: 2 | I17: 3 | J17: 4 | K17: 4 | L17: =SUM(B17:K17) -> 31
A18: Sample4 | B18: 4 | C18: 3 | D18: 2 | E18: 2 | F18: 4 | G18: 4 | H18: 3 | I18: 3 | J18: 4 | K18: 5 | L18: =SUM(B18:K18) -> 34
A19: Sample5 | B19: 1 | C19: 3 | D19: 4 | E19: 3 | F19: 5 | G19: 4 | H19: 5 | I19: 3 | J19: 4 | K19: 7 | L19: =SUM(B19:K19) -> 39
A20: [DiffRhythm] Pathetic film music for orchestra, without choir, f-minor, 80 bpm, 100 seconds
A21: Sample1 | B21: 1 | C21: 1 | D21: 3 | E21: 2 | F21: 4 | G21: 4 | H21: 4 | I21: 5 | J21: 3 | K21: 3 | L21: =SUM(B21:K21) -> 30
A22: Sample2 | B22: 2 | C22: 1 | D22: 2 | E22: 3 | F22: 4 | G22: 3 | H22: 4 | I22: 3 | J22: 3 | K22: 4 | L22: =SUM(B22:K22) -> 29
A23: Sample3 | B23: 4 | C23: 5 | D23: 4 | E23: 4 | F23: 5 | G23: 4 | H23: 3 | I23: 2 | J23: 3 | K23: 7 | L23: =SUM(B23:K23) -> 41
A24: Sample4 | B24: 5 | C24: 4 | D24: 4 | E24: 3 | F24: 4 | G24: 4 | H24: 5 | I24: 5 | J24: 4 | K24: 8 | L24: =SUM(B24:K24) -> 46
A25: Sample5 | B25: 3 | C25: 4 | D25: 4 | E25: 3 | F25: 4 | G25: 5 | H25: 3 | I25: 4 | J25: 4 | K25: 6 | L25: =SUM(B25:K25) -> 40
A26: [DiffRhythm] Energetic techno, synthesizer, e-minor, 140 bpm, 100 seconds
A27: Sample1 | B27: 4 | C27: 5 | D27: 3 | E27: 2 | F27: 4 | G27: 3 | H27: 4 | I27: 4 | J27: 4 | K27: 7 | L27: =SUM(B27:K27) -> 40
A28: Sample2 | B28: 5 | C28: 4 | D28: 3 | E28: 4 | F28: 5 | G28: 5 | H28: 4 | I28: 3 | J28: 3 | K28: 6 | L28: =SUM(B28:K28) -> 42
A29: Sample3 | B29: 2 | C29: 2 | D29: 1 | E29: 4 | F29: 4 | G29: 3 | H29: 2 | I29: 3 | J29: 4 | K29: 4 | L29: =SUM(B29:K29) -> 29
A30: Sample4 | B30: 4 | C30: 4 | D30: 2 | E30: 4 | F30: 5 | G30: 4 | H30: 4 | I30: 3 | J30: 2 | K30: 5 | L30: =SUM(B30:K30) -> 37
A31: Sample5 | B31: 5 | C31: 5 | D31: 4 | E31: 4 | F31: 3 | G31: 5 | H31: 4 | I31: 5 | J31: 3 | K31: 7 | L31: =SUM(B31:K31) -> 45
A32: [DiffRhythm] Relaxing lofi with piano, e-major, 100 bpm, 100 seconds
A33: Sample1 | B33: 2 | C33: 1 | D33: 3 | E33: 3 | F33: 4 | G33: 2 | H33: 4 | I33: 4 | J33: 3 | K33: 4 | L33: =SUM(B33:K33) -> 30
A34: Sample2 | B34: 1 | C34: 1 | D34: 2 | E34: 2 | F34: 4 | G34: 5 | H34: 4 | I34: 4 | J34: 3 | K34: 3 | L34: =SUM(B34:K34) -> 29
A35: Sample3 | B35: 5 | C35: 5 | D35: 4 | E35: 5 | F35: 5 | G35: 4 | H35: 3 | I35: 4 | J35: 3 | K35: 8 | L35: =SUM(B35:K35) -> 46
A36: Sample4 | B36: 3 | C36: 4 | D36: 4 | E36: 3 | F36: 4 | G36: 5 | H36: 4 | I36: 3 | J36: 4 | K36: 4 | L36: =SUM(B36:K36) -> 38
A37: Sample5 | B37: 5 | C37: 4 | D37: 4 | E37: 5 | F37: 5 | G37: 4 | H37: 3 | I37: 2 | J37: 4 | K37: 7 | L37: =SUM(B37:K37) -> 43
A38: [Stable Audio] Pathetic film music for orchestra, without choir, f-minor, 80 bpm, 100 seconds
A39: Sample1 | B39: 5 | C39: 5 | D39: 5 | E39: 4 | F39: 5 | G39: 5 | H39: 4 | I39: 4 | J39: 3 | K39: 8 | L39: =SUM(B39:K39) -> 48
A40: Sample2 | B40: 5 | C40: 5 | D40: 4 | E40: 5 | F40: 4 | G40: 3 | H40: 5 | I40: 5 | J40: 4 | K40: 9 | L40: =SUM(B40:K40) -> 49
...

Sheet SUMA
B1: SUMA
A2: [ACE-Step] Pathetic film music for orchestra, without choir, f-minor, 80 bpm, 100 seconds
A3: Sample1 | B3: =SUM(MB!L3,SK!L3,JW!L3) -> 80
A4: Sample2 | B4: =SUM(MB!L4,SK!L4,JW!L4) -> 99
A5: Sample3 | B5: =SUM(MB!L5,SK!L5,JW!L5) -> 102
A6: Sample4 | B6: =SUM(MB!L6,SK!L6,JW!L6) -> 94
A7: Sample5 | B7: =SUM(MB!L7,SK!L7,JW!L7) -> 95
A8: [ACE-Step] Energetic techno, synthesizer, e-minor, 140 bpm, 100 seconds
A9: Sample1 | B9: =SUM(MB!L9,SK!L9,JW!L9) -> 91
A10: Sample2 | B10: =SUM(MB!L10,SK!L10,JW!L10) -> 82
A11: Sample3 | B11: =SUM(MB!L11,SK!L11,JW!L11) -> 79
A12: Sample4 | B12: =SUM(MB!L12,SK!L12,JW!L12) -> 86
A13: Sample5 | B13: =SUM(MB!L13,SK!L13,JW!L13) -> 102
A14: [ACE-Step] Relaxing lofi with piano, e-major, 100 bpm, 100 seconds
A15: Sample1 | B15: =SUM(MB!L15,SK!L15,JW!L15) -> 85
A16: Sample2 | B16: =SUM(MB!L16,SK!L16,JW!L16) -> 103
A17: Sample3 | B17: =SUM(MB!L17,SK!L17,JW!L17) -> 67
A18: Sample4 | B18: =SUM(MB!L18,SK!L18,JW!L18) -> 77
A19: Sample5 | B19: =SUM(MB!L19,SK!L19,JW!L19) -> 82
A20: [DiffRhythm] Pathetic film music for orchestra, without choir, f-minor, 80 bpm, 100 seconds
A21: Sample1 | B21: =SUM(MB!L21,SK!L21,JW!L21) -> 64
A22: Sample2 | B22: =SUM(MB!L22,SK!L22,JW!L22) -> 63
A23: Sample3 | B23: =SUM(MB!L23,SK!L23,JW!L23) -> 82
A24: Sample4 | B24: =SUM(MB!L24,SK!L24,JW!L24) -> 88
A25: Sample5 | B25: =SUM(MB!L25,SK!L25,JW!L25) -> 94
A26: [DiffRhythm] Energetic techno, synthesizer, e-minor, 140 bpm, 100 seconds
A27: Sample1 | B27: =SUM(MB!L27,SK!L27,JW!L27) -> 81
A28: Sample2 | B28: =SUM(MB!L28,SK!L28,JW!L28) -> 90
A29: Sample3 | B29: =SUM(MB!L29,SK!L29,JW!L29) -> 70
A30: Sample4 | B30: =SUM(MB!L30,SK!L30,JW!L30) -> 80
A31: Sample5 | B31: =SUM(MB!L31,SK!L31,JW!L31) -> 103
A32: [DiffRhythm] Relaxing lofi with piano, e-major, 100 bpm, 100 seconds
A33: Sample1 | B33: =SUM(MB!L33,SK!L33,JW!L33) -> 79
A34: Sample2 | B34: =SUM(MB!L34,SK!L34,JW!L34) -> 63
A35: Sample3 | B35: =SUM(MB!L35,SK!L35,JW!L35) -> 122
A36: Sample4 | B36: =SUM(MB!L36,SK!L36,JW!L36) -> 75
A37: Sample5 | B37: =SUM(MB!L37,SK!L37,JW!L37) -> 95
A38: [Stable Audio] Pathetic film music for orchestra, without choir, f-minor, 80 bpm, 100 seconds
A39: Sample1 | B39: =SUM(MB!L39,SK!L39,JW!L39) -> 129
A40: Sample2 | B40: =SUM(MB!L40,SK!L40,JW!L40) -> 129
...

Sheet OCENA
B1: Ocena Jakościowa | C1: Ocena Ilościowa | D1: SUMA
A2: [ACE-Step] Pathetic film music for orchestra, without choir, f-minor, 80 bpm, 100 seconds | G2: Ocena jakościowa: 75%
A3: Sample1 | B3: =ROUND((SUMA!B3 - 10) * 75/155,0) -> 34 | C3: =ROUND(9 * 25/12, 0) -> 19 | D3: =SUM(B3,C3) -> 53 | G3: Ocena ilościowa: 25%
A4: Sample2 | B4: =ROUND((SUMA!B4 - 10) * 75/155,0) -> 43 | C4: =ROUND(9 * 25/12, 0) -> 19 | D4: =SUM(B4,C4) -> 62
A5: Sample3 | B5: =ROUND((SUMA!B5 - 10) * 75/155,0) -> 45 | C5: =ROUND(11 * 25/12, 0) -> 23 | D5: =SUM(B5,C5) -> 68
A6: Sample4 | B6: =ROUND((SUMA!B6 - 10) * 75/155,0) -> 41 | C6: =ROUND(11 * 25/12, 0) -> 23 | D6: =SUM(B6,C6) -> 64
A7: Sample5 | B7: =ROUND((SUMA!B7 - 10) * 75/155,0) -> 41 | C7: =ROUND(11 * 25/12, 0) -> 23 | D7: =SUM(B7,C7) -> 64
A8: [ACE-Step] Energetic techno, synthesizer, e-minor, 140 bpm, 100 seconds
A9: Sample1 | B9: =ROUND((SUMA!B9 - 10) * 75/155,0) -> 39 | C9: =ROUND(9 * 25/12, 0) -> 19 | D9: =SUM(B9,C9) -> 58
A10: Sample2 | B10: =ROUND((SUMA!B10 - 10) * 75/155,0) -> 35 | C10: =ROUND(8 * 25/12, 0) -> 17 | D10: =SUM(B10,C10) -> 52
A11: Sample3 | B11: =ROUND((SUMA!B11 - 10) * 75/155,0) -> 33 | C11: =ROUND(8 * 25/12, 0) -> 17 | D11: =SUM(B11,C11) -> 50
A12: Sample4 | B12: =ROUND((SUMA!B12 - 10) * 75/155,0) -> 37 | C12: =ROUND(9 * 25/12, 0) -> 19 | D12: =SUM(B12,C12) -> 56
A13: Sample5 | B13: =ROUND((SUMA!B13 - 10) * 75/155,0) -> 45 | C13: =ROUND(9 * 25/12, 0) -> 19 | D13: =SUM(B13,C13) -> 64
A14: [ACE-Step] Relaxing lofi with piano, e-major, 100 bpm, 100 seconds
A15: Sample1 | B15: =ROUND((SUMA!B15 - 10) * 75/155,0) -> 36 | C15: =ROUND(10 * 25/12, 0) -> 21 | D15: =SUM(B15,C15) -> 57
A16: Sample2 | B16: =ROUND((SUMA!B16 - 10) * 75/155,0) -> 45 | C16: =ROUND(9 * 25/12, 0) -> 19 | D16: =SUM(B16,C16) -> 64
A17: Sample3 | B17: =ROUND((SUMA!B17 - 10) * 75/155,0) -> 28 | C17: =ROUND(11 * 25/12, 0) -> 23 | D17: =SUM(B17,C17) -> 51
A18: Sample4 | B18: =ROUND((SUMA!B18 - 10) * 75/155,0) -> 32 | C18: =ROUND(9 * 25/12, 0) -> 19 | D18: =SUM(B18,C18) -> 51
A19: Sample5 | B19: =ROUND((SUMA!B19 - 10) * 75/155,0) -> 35 | C19: =ROUND(8 * 25/12, 0) -> 17 | D19: =SUM(B19,C19) -> 52
A20: [DiffRhythm] Pathetic film music for orchestra, without choir, f-minor, 80 bpm, 100 seconds
A21: Sample1 | B21: =ROUND((SUMA!B21 - 10) * 75/155,0) -> 26 | C21: =ROUND(12 * 25/12, 0) -> 25 | D21: =SUM(B21,C21) -> 51
A22: Sample2 | B22: =ROUND((SUMA!B22 - 10) * 75/155,0) -> 26 | C22: =ROUND(10 * 25/12, 0) -> 21 | D22: =SUM(B22,C22) -> 47
A23: Sample3 | B23: =ROUND((SUMA!B23 - 10) * 75/155,0) -> 35 | C23: =ROUND(11 * 25/12, 0) -> 23 | D23: =SUM(B23,C23) -> 58
A24: Sample4 | B24: =ROUND((SUMA!B24 - 10) * 75/155,0) -> 38 | C24: =ROUND(11 * 25/12, 0) -> 23 | D24: =SUM(B24,C24) -> 61
A25: Sample5 | B25: =ROUND((SUMA!B25 - 10) * 75/155,0) -> 41 | C25: =ROUND(11 * 25/12, 0) -> 23 | D25: =SUM(B25,C25) -> 64
A26: [DiffRhythm] Energetic techno, synthesizer, e-minor, 140 bpm, 100 seconds
A27: Sample1 | B27: =ROUND((SUMA!B27 - 10) * 75/155,0) -> 34 | C27: =ROUND(10 * 25/12, 0) -> 21 | D27: =SUM(B27,C27) -> 55
A28: Sample2 | B28: =ROUND((SUMA!B28 - 10) * 75/155,0) -> 39 | C28: =ROUND(9 * 25/12, 0) -> 19 | D28: =SUM(B28,C28) -> 58
A29: Sample3 | B29: =ROUND((SUMA!B29 - 10) * 75/155,0) -> 29 | C29: =ROUND(11 * 25/12, 0) -> 23 | D29: =SUM(B29,C29) -> 52
A30: Sample4 | B30: =ROUND((SUMA!B30 - 10) * 75/155,0) -> 34 | C30: =ROUND(9 * 25/12, 0) -> 19 | D30: =SUM(B30,C30) -> 53
A31: Sample5 | B31: =ROUND((SUMA!B31 - 10) * 75/155,0) -> 45 | C31: =ROUND(11 * 25/12, 0) -> 23 | D31: =SUM(B31,C31) -> 68
A32: [DiffRhythm] Relaxing lofi with piano, e-major, 100 bpm, 100 seconds
A33: Sample1 | B33: =ROUND((SUMA!B33 - 10) * 75/155,0) -> 33 | C33: =ROUND(11 * 25/12, 0) -> 23 | D33: =SUM(B33,C33) -> 56
A34: Sample2 | B34: =ROUND((SUMA!B34 - 10) * 75/155,0) -> 26 | C34: =ROUND(9 * 25/12, 0) -> 19 | D34: =SUM(B34,C34) -> 45
A35: Sample3 | B35: =ROUND((SUMA!B35 - 10) * 75/155,0) -> 54 | C35: =ROUND(11 * 25/12, 0) -> 23 | D35: =SUM(B35,C35) -> 77
A36: Sample4 | B36: =ROUND((SUMA!B36 - 10) * 75/155,0) -> 31 | C36: =ROUND(11 * 25/12, 0) -> 23 | D36: =SUM(B36,C36) -> 54
A37: Sample5 | B37: =ROUND((SUMA!B37 - 10) * 75/155,0) -> 41 | C37: =ROUND(8 * 25/12, 0) -> 17 | D37: =SUM(B37,C37) -> 58
A38: [Stable Audio] Pathetic film music for orchestra, without choir, f-minor, 80 bpm, 100 seconds
A39: Sample1 | B39: =ROUND((SUMA!B39 - 10) * 75/155,0) -> 58 | C39: =ROUND(12 * 25/12, 0) -> 25 | D39: =SUM(B39,C39) -> 83
A40: Sample2 | B40: =ROUND((SUMA!B40 - 10) * 75/155,0) -> 58 | C40: =ROUND(11 * 25/12, 0) -> 23 | D40: =SUM(B40,C40) -> 81
...
